Workbook

Sheet 모델촬영리스트
B2: ★스튜디오에서 관리합니다.
B3: ★촬영일자별로 누적 관리할 것, 앞으로 이 양식으로 촬영리스트 관리하면 됩니다.
B4: 브랜드 | C4: 로엠
B5: 순서 | C5: 스타일코드 | D5: 촬영일자 | E5: 비고
B6: 1 | D6: 42999 | E6: 촬영완료
B7: 2 | D7: 42999 | E7: 촬영완료
B8: 3 | D8: 42999 | E8: 촬영완료
B9: 4 | D9: 42999 | E9: 촬영완료
B10: 5 | D10: 42999 | E10: 촬영완료
B11: 6 | D11: 42999 | E11: 촬영완료
B12: 7 | D12: 42999 | E12: 촬영완료
B13: 8 | D13: 42999 | E13: 촬영완료
B14: 9 | D14: 42999 | E14: 촬영완료
B15: 10 | D15: 42999 | E15: 촬영완료
B16: 11 | D16: 42999 | E16: 촬영완료
B17: 12 | D17: 42999 | E17: 촬영완료
... B39: 34 | D39: 42999 | E39: 촬영완료

Sheet 배너촬영리스트
B2: ★브랜드에서 전달 예정입니다. 리스트 받으면 스타일코드에 해당 스타일만 붙여넣기하면 됩니다.
B3: ★촬영일자별로 누적 관리할 것, 앞으로 이 양식으로 촬영리스트 관리하면 됩니다.
B4: 브랜드 | C4: 로엠
B5: 순서 | C5: 스타일코드 | D5: 촬영일자 | E5: 비고
B6: 1 | D6: 43024 | E6: 배너촬영
B7: 2 | D7: 43024 | E7: 배너촬영
B8: 3 | D8: 43024 | E8: 배너촬영
B9: 4 | D9: 43024 | E9: 배너촬영
B10: 5 | D10: 43024 | E10: 배너촬영
B11: 6 | D11: 43024 | E11: 배너촬영
B12: 7 | D12: 43024 | E12: 배너촬영
B13: 8 | D13: 43024 | E13: 배너촬영
B14: 9 | D14: 43024 | E14: 배너촬영
B15: 10 | D15: 43024 | E15: 배너촬영
B16: 11 | D16: 43024 | E16: 배너촬영
B17: 12 | D17: 43024 | E17: 배너촬영
... B76: 71 | D76: 43024 | E76: 배너촬영

Sheet RM시즌체크판
V1: RM
B2: 온라인 상품 등록 체크판 | L2: 전체sty | M2: =COUNTIF(B7:B4481,$B$3) -> 411 | N2: 업데이트 | O2: =#REF! -> #REF! | V2: CV
B3: RM | L3: 등록 | M3: =COUNTIFS(B7:$B$362,$B$3,G7:$G$362,$L$3) -> 0 | V3: TM
L4: 등록율 | M4: =M3/M2 -> 0
B5: 브랜드 | C5: 스타일코드 | D5: 스타일명 | E5: 정판가 | F5: 최초출고일 | G5: 등록여부 | H5: 상품컷 (컬러별)_단품촬영 후 컬러링 표기로 체크할 것! | N5: 착장컷 | O5: 배너컷 | P5: 배너촬영일
H6: 컬러1 | I6: 컬러2 | J6: 컬러3 | K6: 컬러4 | L6: 컬러5 | M6: 컬러6
B7: =MID(C7,1,2) -> RM | C7: RMAP747R01 | D7: =VLOOKUP(C7,#REF!,2,0) -> #REF! | E7: =VLOOKUP(C7,#REF!,4,0) -> #REF! | F7: =VLOOKUP(C7,#REF!,8,0) -> #REF! | G7: =IF(ISERROR(IF(VLOOKUP(C7,#REF!,2,0)>0,"등록","")),"",(IF(VLOOKUP(C7,#REF!,2,0)>0,"등록",""))) | H7: {=IF(ISERROR(OFFSET(#REF!,SMALL(IF(#REF!=RM시즌체크판!C7,ROW(#REF!)-20),1),)),"",(OFFSET(#REF!,SMALL(IF(#REF!=RM시즌체크판!C7,ROW(#REF!)-20),1),)))} | I7: {=IF(ISERROR(OFFSET(#REF!,SMALL(IF(#REF!=RM시즌체크판!C7,ROW(#REF!)-20),2),)),"",(OFFSET(#REF!,SMALL(IF(#REF!=RM시즌체크판!C7,ROW(#REF!)-20),2),)))} | J7: {=IF(ISERROR(OFFSET(#REF!,SMALL(IF(#REF!=RM시즌체크판!C7,ROW(#REF!)-20),3),)),"",(OFFSET(#REF!,SMALL(IF(#REF!=RM시즌체크판!C7,ROW(#REF!)-20),3),)))} | K7: {=IF(ISERROR(OFFSET(#REF!,SMALL(IF(#REF!=RM시즌체크판!C7,ROW(#REF!)-20),4),)),"",(OFFSET(#REF!,SMALL(IF(#REF!=RM시즌체크판!C7,ROW(#REF!)-20),4),)))} | L7: {=IF(ISERROR(OFFSET(#REF!,SMALL(IF(#REF!=RM시즌체크판!C7,ROW(#REF!)-20),5),)),"",(OFFSET(#REF!,SMALL(IF(#REF!=RM시즌체크판!C7,ROW(#REF!)-20),5),)))} | M7: {=IF(ISERROR(OFFSET(#REF!,SMALL(IF(#REF!=RM시즌체크판!C7,ROW(#REF!)-20),6),)),"",(OFFSET(#REF!,SMALL(IF(#REF!=RM시즌체크판!C7,ROW(#REF!)-20),6),)))} | N7: =IF(ISERROR(VLOOKUP(C7,모델촬영리스트!$C:$E,3,)),"",(VLOOKUP(C7,모델촬영리스트!$C:$E,3,))) | O7: =IF(ISERROR(VLOOKUP(C7,배너촬영리스트!$C:$E,3,)),"",(VLOOKUP(C7,배너촬영리스트!$C:$E,3,))) | P7: =IF(ISERROR(VLOOKUP(C7,배너촬영리스트!$C:$E,2,)),"",(VLOOKUP(C7,배너촬영리스트!$C:$E,2,)))
B8: =MID(C8,1,2) -> RM | C8: RMAP747RT2 | D8: =VLOOKUP(C8,#REF!,2,0) -> #REF! | E8: =VLOOKUP(C8,#REF!,4,0) -> #REF! | F8: =VLOOKUP(C8,#REF!,8,0) -> #REF! | G8: =IF(ISERROR(IF(VLOOKUP(C8,#REF!,2,0)>0,"등록","")),"",(IF(VLOOKUP(C8,#REF!,2,0)>0,"등록",""))) | H8: {=IF(ISERROR(OFFSET(#REF!,SMALL(IF(#REF!=RM시즌체크판!C8,ROW(#REF!)-20),1),)),"",(OFFSET(#REF!,SMALL(IF(#REF!=RM시즌체크판!C8,ROW(#REF!)-20),1),)))} | I8: {=IF(ISERROR(OFFSET(#REF!,SMALL(IF(#REF!=RM시즌체크판!C8,ROW(#REF!)-20),2),)),"",(OFFSET(#REF!,SMALL(IF(#REF!=RM시즌체크판!C8,ROW(#REF!)-20),2),)))} | J8: {=IF(ISERROR(OFFSET(#REF!,SMALL(IF(#REF!=RM시즌체크판!C8,ROW(#REF!)-20),3),)),"",(OFFSET(#REF!,SMALL(IF(#REF!=RM시즌체크판!C8,ROW(#REF!)-20),3),)))} | K8: {=IF(ISERROR(OFFSET(#REF!,SMALL(IF(#REF!=RM시즌체크판!C8,ROW(#REF!)-20),4),)),"",(OFFSET(#REF!,SMALL(IF(#REF!=RM시즌체크판!C8,ROW(#REF!)-20),4),)))} | L8: {=IF(ISERROR(OFFSET(#REF!,SMALL(IF(#REF!=RM시즌체크판!C8,ROW(#REF!)-20),5),)),"",(OFFSET(#REF!,SMALL(IF(#REF!=RM시즌체크판!C8,ROW(#REF!)-20),5),)))} | M8: {=IF(ISERROR(OFFSET(#REF!,SMALL(IF(#REF!=RM시즌체크판!C8,ROW(#REF!)-20),6),)),"",(OFFSET(#REF!,SMALL(IF(#REF!=RM시즌체크판!C8,ROW(#REF!)-20),6),)))} | N8: =IF(ISERROR(VLOOKUP(C8,모델촬영리스트!$C:$E,3,)),"",(VLOOKUP(C8,모델촬영리스트!$C:$E,3,))) | O8: =IF(ISERROR(VLOOKUP(C8,배너촬영리스트!$C:$E,3,)),"",(VLOOKUP(C8,배너촬영리스트!$C:$E,3,))) | P8: =IF(ISERROR(VLOOKUP(C8,배너촬영리스트!$C:$E,2,)),"",(VLOOKUP(C8,배너촬영리스트!$C:$E,2,)))
B9: =MID(C9,1,2) -> RM | C9: RMAK748G11 | D9: =VLOOKUP(C9,#REF!,2,0) -> #REF! | E9: =VLOOKUP(C9,#REF!,4,0) -> #REF! | F9: =VLOOKUP(C9,#REF!,8,0) -> #REF! | G9: =IF(ISERROR(IF(VLOOKUP(C9,#REF!,2,0)>0,"등록","")),"",(IF(VLOOKUP(C9,#REF!,2,0)>0,"등록",""))) | H9: {=IF(ISERROR(OFFSET(#REF!,SMALL(IF(#REF!=RM시즌체크판!C9,ROW(#REF!)-20),1),)),"",(OFFSET(#REF!,SMALL(IF(#REF!=RM시즌체크판!C9,ROW(#REF!)-20),1),)))} | I9: {=IF(ISERROR(OFFSET(#REF!,SMALL(IF(#REF!=RM시즌체크판!C9,ROW(#REF!)-20),2),)),"",(OFFSET(#REF!,SMALL(IF(#REF!=RM시즌체크판!C9,ROW(#REF!)-20),2),)))} | J9: {=IF(ISERROR(OFFSET(#REF!,SMALL(IF(#REF!=RM시즌체크판!C9,ROW(#REF!)-20),3),)),"",(OFFSET(#REF!,SMALL(IF(#REF!=RM시즌체크판!C9,ROW(#REF!)-20),3),)))} | K9: {=IF(ISERROR(OFFSET(#REF!,SMALL(IF(#REF!=RM시즌체크판!C9,ROW(#REF!)-20),4),)),"",(OFFSET(#REF!,SMALL(IF(#REF!=RM시즌체크판!C9,ROW(#REF!)-20),4),)))} | L9: {=IF(ISERROR(OFFSET(#REF!,SMALL(IF(#REF!=RM시즌체크판!C9,ROW(#REF!)-20),5),)),"",(OFFSET(#REF!,SMALL(IF(#REF!=RM시즌체크판!C9,ROW(#REF!)-20),5),)))} | M9: {=IF(ISERROR(OFFSET(#REF!,SMALL(IF(#REF!=RM시즌체크판!C9,ROW(#REF!)-20),6),)),"",(OFFSET(#REF!,SMALL(IF(#REF!=RM시즌체크판!C9,ROW(#REF!)-20),6),)))} | N9: =IF(ISERROR(VLOOKUP(C9,모델촬영리스트!$C:$E,3,)),"",(VLOOKUP(C9,모델촬영리스트!$C:$E,3,))) | O9: =IF(ISERROR(VLOOKUP(C9,배너촬영리스트!$C:$E,3,)),"",(VLOOKUP(C9,배너촬영리스트!$C:$E,3,))) | P9: =IF(ISERROR(VLOOKUP(C9,배너촬영리스트!$C:$E,2,)),"",(VLOOKUP(C9,배너촬영리스트!$C:$E,2,)))
B10: =MID(C10,1,2) -> RM | C10: RMAK748G12 | D10: =VLOOKUP(C10,#REF!,2,0) -> #REF! | E10: =VLOOKUP(C10,#REF!,4,0) -> #REF! | F10: =VLOOKUP(C10,#REF!,8,0) -> #REF! | G10: =IF(ISERROR(IF(VLOOKUP(C10,#REF!,2,0)>0,"등록","")),"",(IF(VLOOKUP(C10,#REF!,2,0)>0,"등록",""))) | H10: {=IF(ISERROR(OFFSET(#REF!,SMALL(IF(#REF!=RM시즌체크판!C10,ROW(#REF!)-20),1),)),"",(OFFSET(#REF!,SMALL(IF(#REF!=RM시즌체크판!C10,ROW(#REF!)-20),1),)))} | I10: {=IF(ISERROR(OFFSET(#REF!,SMALL(IF(#REF!=RM시즌체크판!C10,ROW(#REF!)-20),2),)),"",(OFFSET(#REF!,SMALL(IF(#REF!=RM시즌체크판!C10,ROW(#REF!)-20),2),)))} | J10: {=IF(ISERROR(OFFSET(#REF!,SMALL(IF(#REF!=RM시즌체크판!C10,ROW(#REF!)-20),3),)),"",(OFFSET(#REF!,SMALL(IF(#REF!=RM시즌체크판!C10,ROW(#REF!)-20),3),)))} | K10: {=IF(ISERROR(OFFSET(#REF!,SMALL(IF(#REF!=RM시즌체크판!C10,ROW(#REF!)-20),4),)),"",(OFFSET(#REF!,SMALL(IF(#REF!=RM시즌체크판!C10,ROW(#REF!)-20),4),)))} | L10: {=IF(ISERROR(OFFSET(#REF!,SMALL(IF(#REF!=RM시즌체크판!C10,ROW(#REF!)-20),5),)),"",(OFFSET(#REF!,SMALL(IF(#REF!=RM시즌체크판!C10,ROW(#REF!)-20),5),)))} | M10: {=IF(ISERROR(OFFSET(#REF!,SMALL(IF(#REF!=RM시즌체크판!C10,ROW(#REF!)-20),6),)),"",(OFFSET(#REF!,SMALL(IF(#REF!=RM시즌체크판!C10,ROW(#REF!)-20),6),)))} | N10: =IF(ISERROR(VLOOKUP(C10,모델촬영리스트!$C:$E,3,)),"",(VLOOKUP(C10,모델촬영리스트!$C:$E,3,))) | O10: =IF(ISERROR(VLOOKUP(C10,배너촬영리스트!$C:$E,3,)),"",(VLOOKUP(C10,배너촬영리스트!$C:$E,3,))) | P10: =IF(ISERROR(VLOOKUP(C10,배너촬영리스트!$C:$E,2,)),"",(VLOOKUP(C10,배너촬영리스트!$C:$E,2,)))
B11: =MID(C11,1,2) -> RM | C11: RMAK748G13 | D11: =VLOOKUP(C11,#REF!,2,0) -> #REF! | E11: =VLOOKUP(C11,#REF!,4,0) -> #REF! | F11: =VLOOKUP(C11,#REF!,8,0) -> #REF! | G11: =IF(ISERROR(IF(VLOOKUP(C11,#REF!,2,0)>0,"등록","")),"",(IF(VLOOKUP(C11,#REF!,2,0)>0,"등록",""))) | H11: {=IF(ISERROR(OFFSET(#REF!,SMALL(IF(#REF!=RM시즌체크판!C11,ROW(#REF!)-20),1),)),"",(OFFSET(#REF!,SMALL(IF(#REF!=RM시즌체크판!C11,ROW(#REF!)-20),1),)))} | I11: {=IF(ISERROR(OFFSET(#REF!,SMALL(IF(#REF!=RM시즌체크판!C11,ROW(#REF!)-20),2),)),"",(OFFSET(#REF!,SMALL(IF(#REF!=RM시즌체크판!C11,ROW(#REF!)-20),2),)))} | J11: {=IF(ISERROR(OFFSET(#REF!,SMALL(IF(#REF!=RM시즌체크판!C11,ROW(#REF!)-20),3),)),"",(OFFSET(#REF!,SMALL(IF(#REF!=RM시즌체크판!C11,ROW(#REF!)-20),3),)))} | K11: {=IF(ISERROR(OFFSET(#REF!,SMALL(IF(#REF!=RM시즌체크판!C11,ROW(#REF!)-20),4),)),"",(OFFSET(#REF!,SMALL(IF(#REF!=RM시즌체크판!C11,ROW(#REF!)-20),4),)))} | L11: {=IF(ISERROR(OFFSET(#REF!,SMALL(IF(#REF!=RM시즌체크판!C11,ROW(#REF!)-20),5),)),"",(OFFSET(#REF!,SMALL(IF(#REF!=RM시즌체크판!C11,ROW(#REF!)-20),5),)))} | M11: {=IF(ISERROR(OFFSET(#REF!,SMALL(IF(#REF!=RM시즌체크판!C11,ROW(#REF!)-20),6),)),"",(OFFSET(#REF!,SMALL(IF(#REF!=RM시즌체크판!C11,ROW(#REF!)-20),6),)))} | N11: =IF(ISERROR(VLOOKUP(C11,모델촬영리스트!$C:$E,3,)),"",(VLOOKUP(C11,모델촬영리스트!$C:$E,3,))) | O11: =IF(ISERROR(VLOOKUP(C11,배너촬영리스트!$C:$E,3,)),"",(VLOOKUP(C11,배너촬영리스트!$C:$E,3,))) | P11: =IF(ISERROR(VLOOKUP(C11,배너촬영리스트!$C:$E,2,)),"",(VLOOKUP(C11,배너촬영리스트!$C:$E,2,)))
B12: =MID(C12,1,2) -> RM | C12: RMAK748R11 | D12: =VLOOKUP(C12,#REF!,2,0) -> #REF! | E12: =VLOOKUP(C12,#REF!,4,0) -> #REF! | F12: =VLOOKUP(C12,#REF!,8,0) -> #REF! | G12: =IF(ISERROR(IF(VLOOKUP(C12,#REF!,2,0)>0,"등록","")),"",(IF(VLOOKUP(C12,#REF!,2,0)>0,"등록",""))) | H12: {=IF(ISERROR(OFFSET(#REF!,SMALL(IF(#REF!=RM시즌체크판!C12,ROW(#REF!)-20),1),)),"",(OFFSET(#REF!,SMALL(IF(#REF!=RM시즌체크판!C12,ROW(#REF!)-20),1),)))} | I12: {=IF(ISERROR(OFFSET(#REF!,SMALL(IF(#REF!=RM시즌체크판!C12,ROW(#REF!)-20),2),)),"",(OFFSET(#REF!,SMALL(IF(#REF!=RM시즌체크판!C12,ROW(#REF!)-20),2),)))} | J12: {=IF(ISERROR(OFFSET(#REF!,SMALL(IF(#REF!=RM시즌체크판!C12,ROW(#REF!)-20),3),)),"",(OFFSET(#REF!,SMALL(IF(#REF!=RM시즌체크판!C12,ROW(#REF!)-20),3),)))} | K12: {=IF(ISERROR(OFFSET(#REF!,SMALL(IF(#REF!=RM시즌체크판!C12,ROW(#REF!)-20),4),)),"",(OFFSET(#REF!,SMALL(IF(#REF!=RM시즌체크판!C12,ROW(#REF!)-20),4),)))} | L12: {=IF(ISERROR(OFFSET(#REF!,SMALL(IF(#REF!=RM시즌체크판!C12,ROW(#REF!)-20),5),)),"",(OFFSET(#REF!,SMALL(IF(#REF!=RM시즌체크판!C12,ROW(#REF!)-20),5),)))} | M12: {=IF(ISERROR(OFFSET(#REF!,SMALL(IF(#REF!=RM시즌체크판!C12,ROW(#REF!)-20),6),)),"",(OFFSET(#REF!,SMALL(IF(#REF!=RM시즌체크판!C12,ROW(#REF!)-20),6),)))} | N12: =IF(ISERROR(VLOOKUP(C12,모델촬영리스트!$C:$E,3,)),"",(VLOOKUP(C12,모델촬영리스트!$C:$E,3,))) | O12: =IF(ISERROR(VLOOKUP(C12,배너촬영리스트!$C:$E,3,)),"",(VLOOKUP(C12,배너촬영리스트!$C:$E,3,))) | P12: =IF(ISERROR(VLOOKUP(C12,배너촬영리스트!$C:$E,2,)),"",(VLOOKUP(C12,배너촬영리스트!$C:$E,2,)))
B13: =MID(C13,1,2) -> RM | C13: RMAS748RT1 | D13: =VLOOKUP(C13,#REF!,2,0) -> #REF! | E13: =VLOOKUP(C13,#REF!,4,0) -> #REF! | F13: =VLOOKUP(C13,#REF!,8,0) -> #REF! | G13: =IF(ISERROR(IF(VLOOKUP(C13,#REF!,2,0)>0,"등록","")),"",(IF(VLOOKUP(C13,#REF!,2,0)>0,"등록",""))) | H13: {=IF(ISERROR(OFFSET(#REF!,SMALL(IF(#REF!=RM시즌체크판!C13,ROW(#REF!)-20),1),)),"",(OFFSET(#REF!,SMALL(IF(#REF!=RM시즌체크판!C13,ROW(#REF!)-20),1),)))} | I13: {=IF(ISERROR(OFFSET(#REF!,SMALL(IF(#REF!=RM시즌체크판!C13,ROW(#REF!)-20),2),)),"",(OFFSET(#REF!,SMALL(IF(#REF!=RM시즌체크판!C13,ROW(#REF!)-20),2),)))} | J13: {=IF(ISERROR(OFFSET(#REF!,SMALL(IF(#REF!=RM시즌체크판!C13,ROW(#REF!)-20),3),)),"",(OFFSET(#REF!,SMALL(IF(#REF!=RM시즌체크판!C13,ROW(#REF!)-20),3),)))} | K13: {=IF(ISERROR(OFFSET(#REF!,SMALL(IF(#REF!=RM시즌체크판!C13,ROW(#REF!)-20),4),)),"",(OFFSET(#REF!,SMALL(IF(#REF!=RM시즌체크판!C13,ROW(#REF!)-20),4),)))} | L13: {=IF(ISERROR(OFFSET(#REF!,SMALL(IF(#REF!=RM시즌체크판!C13,ROW(#REF!)-20),5),)),"",(OFFSET(#REF!,SMALL(IF(#REF!=RM시즌체크판!C13,ROW(#REF!)-20),5),)))} | M13: {=IF(ISERROR(OFFSET(#REF!,SMALL(IF(#REF!=RM시즌체크판!C13,ROW(#REF!)-20),6),)),"",(OFFSET(#REF!,SMALL(IF(#REF!=RM시즌체크판!C13,ROW(#REF!)-20),6),)))} | N13: =IF(ISERROR(VLOOKUP(C13,모델촬영리스트!$C:$E,3,)),"",(VLOOKUP(C13,모델촬영리스트!$C:$E,3,))) | O13: =IF(ISERROR(VLOOKUP(C13,배너촬영리스트!$C:$E,3,)),"",(VLOOKUP(C13,배너촬영리스트!$C:$E,3,))) | P13: =IF(ISERROR(VLOOKUP(C13,배너촬영리스트!$C:$E,2,)),"",(VLOOKUP(C13,배너촬영리스트!$C:$E,2,)))
B14: =MID(C14,1,2) -> RM | C14: RMAS748RT2 | D14: =VLOOKUP(C14,#REF!,2,0) -> #REF! | E14: =VLOOKUP(C14,#REF!,4,0) -> #REF! | F14: =VLOOKUP(C14,#REF!,8,0) -> #REF! | G14: =IF(ISERROR(IF(VLOOKUP(C14,#REF!,2,0)>0,"등록","")),"",(IF(VLOOKUP(C14,#REF!,2,0)>0,"등록",""))) | H14: {=IF(ISERROR(OFFSET(#REF!,SMALL(IF(#REF!=RM시즌체크판!C14,ROW(#REF!)-20),1),)),"",(OFFSET(#REF!,SMALL(IF(#REF!=RM시즌체크판!C14,ROW(#REF!)-20),1),)))} | I14: {=IF(ISERROR(OFFSET(#REF!,SMALL(IF(#REF!=RM시즌체크판!C14,ROW(#REF!)-20),2),)),"",(OFFSET(#REF!,SMALL(IF(#REF!=RM시즌체크판!C14,ROW(#REF!)-20),2),)))} | J14: {=IF(ISERROR(OFFSET(#REF!,SMALL(IF(#REF!=RM시즌체크판!C14,ROW(#REF!)-20),3),)),"",(OFFSET(#REF!,SMALL(IF(#REF!=RM시즌체크판!C14,ROW(#REF!)-20),3),)))} | K14: {=IF(ISERROR(OFFSET(#REF!,SMALL(IF(#REF!=RM시즌체크판!C14,ROW(#REF!)-20),4),)),"",(OFFSET(#REF!,SMALL(IF(#REF!=RM시즌체크판!C14,ROW(#REF!)-20),4),)))} | L14: {=IF(ISERROR(OFFSET(#REF!,SMALL(IF(#REF!=RM시즌체크판!C14,ROW(#REF!)-20),5),)),"",(OFFSET(#REF!,SMALL(IF(#REF!=RM시즌체크판!C14,ROW(#REF!)-20),5),)))} | M14: {=IF(ISERROR(OFFSET(#REF!,SMALL(IF(#REF!=RM시즌체크판!C14,ROW(#REF!)-20),6),)),"",(OFFSET(#REF!,SMALL(IF(#REF!=RM시즌체크판!C14,ROW(#REF!)-20),6),)))} | N14: =IF(ISERROR(VLOOKUP(C14,모델촬영리스트!$C:$E,3,)),"",(VLOOKUP(C14,모델촬영리스트!$C:$E,3,))) | O14: =IF(ISERROR(VLOOKUP(C14,배너촬영리스트!$C:$E,3,)),"",(VLOOKUP(C14,배너촬영리스트!$C:$E,3,))) | P14: =IF(ISERROR(VLOOKUP(C14,배너촬영리스트!$C:$E,2,)),"",(VLOOKUP(C14,배너촬영리스트!$C:$E,2,)))
B15: =MID(C15,1,2) -> RM | C15: RMAS748RT3 | D15: =VLOOKUP(C15,#REF!,2,0) -> #REF! | E15: =VLOOKUP(C15,#REF!,4,0) -> #REF! | F15: =VLOOKUP(C15,#REF!,8,0) -> #REF! | G15: =IF(ISERROR(IF(VLOOKUP(C15,#REF!,2,0)>0,"등록","")),"",(IF(VLOOKUP(C15,#REF!,2,0)>0,"등록",""))) | H15: {=IF(ISERROR(OFFSET(#REF!,SMALL(IF(#REF!=RM시즌체크판!C15,ROW(#REF!)-20),1),)),"",(OFFSET(#REF!,SMALL(IF(#REF!=RM시즌체크판!C15,ROW(#REF!)-20),1),)))} | I15: {=IF(ISERROR(OFFSET(#REF!,SMALL(IF(#REF!=RM시즌체크판!C15,ROW(#REF!)-20),2),)),"",(OFFSET(#REF!,SMALL(IF(#REF!=RM시즌체크판!C15,ROW(#REF!)-20),2),)))} | J15: {=IF(ISERROR(OFFSET(#REF!,SMALL(IF(#REF!=RM시즌체크판!C15,ROW(#REF!)-20),3),)),"",(OFFSET(#REF!,SMALL(IF(#REF!=RM시즌체크판!C15,ROW(#REF!)-20),3),)))} | K15: {=IF(ISERROR(OFFSET(#REF!,SMALL(IF(#REF!=RM시즌체크판!C15,ROW(#REF!)-20),4),)),"",(OFFSET(#REF!,SMALL(IF(#REF!=RM시즌체크판!C15,ROW(#REF!)-20),4),)))} | L15: {=IF(ISERROR(OFFSET(#REF!,SMALL(IF(#REF!=RM시즌체크판!C15,ROW(#REF!)-20),5),)),"",(OFFSET(#REF!,SMALL(IF(#REF!=RM시즌체크판!C15,ROW(#REF!)-20),5),)))} | M15: {=IF(ISERROR(OFFSET(#REF!,SMALL(IF(#REF!=RM시즌체크판!C15,ROW(#REF!)-20),6),)),"",(OFFSET(#REF!,SMALL(IF(#REF!=RM시즌체크판!C15,ROW(#REF!)-20),6),)))} | N15: =IF(ISERROR(VLOOKUP(C15,모델촬영리스트!$C:$E,3,)),"",(VLOOKUP(C15,모델촬영리스트!$C:$E,3,))) | O15: =IF(ISERROR(VLOOKUP(C15,배너촬영리스트!$C:$E,3,)),"",(VLOOKUP(C15,배너촬영리스트!$C:$E,3,))) | P15: =IF(ISERROR(VLOOKUP(C15,배너촬영리스트!$C:$E,2,)),"",(VLOOKUP(C15,배너촬영리스트!$C:$E,2,)))
B16: =MID(C16,1,2) -> RM | C16: RMAS748RT4 | D16: =VLOOKUP(C16,#REF!,2,0) -> #REF! | E16: =VLOOKUP(C16,#REF!,4,0) -> #REF! | F16: =VLOOKUP(C16,#REF!,8,0) -> #REF! | G16: =IF(ISERROR(IF(VLOOKUP(C16,#REF!,2,0)>0,"등록","")),"",(IF(VLOOKUP(C16,#REF!,2,0)>0,"등록",""))) | H16: {=IF(ISERROR(OFFSET(#REF!,SMALL(IF(#REF!=RM시즌체크판!C16,ROW(#REF!)-20),1),)),"",(OFFSET(#REF!,SMALL(IF(#REF!=RM시즌체크판!C16,ROW(#REF!)-20),1),)))} | I16: {=IF(ISERROR(OFFSET(#REF!,SMALL(IF(#REF!=RM시즌체크판!C16,ROW(#REF!)-20),2),)),"",(OFFSET(#REF!,SMALL(IF(#REF!=RM시즌체크판!C16,ROW(#REF!)-20),2),)))} | J16: {=IF(ISERROR(OFFSET(#REF!,SMALL(IF(#REF!=RM시즌체크판!C16,ROW(#REF!)-20),3),)),"",(OFFSET(#REF!,SMALL(IF(#REF!=RM시즌체크판!C16,ROW(#REF!)-20),3),)))} | K16: {=IF(ISERROR(OFFSET(#REF!,SMALL(IF(#REF!=RM시즌체크판!C16,ROW(#REF!)-20),4),)),"",(OFFSET(#REF!,SMALL(IF(#REF!=RM시즌체크판!C16,ROW(#REF!)-20),4),)))} | L16: {=IF(ISERROR(OFFSET(#REF!,SMALL(IF(#REF!=RM시즌체크판!C16,ROW(#REF!)-20),5),)),"",(OFFSET(#REF!,SMALL(IF(#REF!=RM시즌체크판!C16,ROW(#REF!)-20),5),)))} | M16: {=IF(ISERROR(OFFSET(#REF!,SMALL(IF(#REF!=RM시즌체크판!C16,ROW(#REF!)-20),6),)),"",(OFFSET(#REF!,SMALL(IF(#REF!=RM시즌체크판!C16,ROW(#REF!)-20),6),)))} | N16: =IF(ISERROR(VLOOKUP(C16,모델촬영리스트!$C:$E,3,)),"",(VLOOKUP(C16,모델촬영리스트!$C:$E,3,))) | O16: =IF(ISERROR(VLOOKUP(C16,배너촬영리스트!$C:$E,3,)),"",(VLOOKUP(C16,배너촬영리스트!$C:$E,3,))) | P16: =IF(ISERROR(VLOOKUP(C16,배너촬영리스트!$C:$E,2,)),"",(VLOOKUP(C16,배너촬영리스트!$C:$E,2,)))
B17: =MID(C17,1,2) -> RM | C17: RMAS748RT5 | D17: =VLOOKUP(C17,#REF!,2,0) -> #REF! | E17: =VLOOKUP(C17,#REF!,4,0) -> #REF! | F17: =VLOOKUP(C17,#REF!,8,0) -> #REF! | G17: =IF(ISERROR(IF(VLOOKUP(C17,#REF!,2,0)>0,"등록","")),"",(IF(VLOOKUP(C17,#REF!,2,0)>0,"등록",""))) | H17: {=IF(ISERROR(OFFSET(#REF!,SMALL(IF(#REF!=RM시즌체크판!C17,ROW(#REF!)-20),1),)),"",(OFFSET(#REF!,SMALL(IF(#REF!=RM시즌체크판!C17,ROW(#REF!)-20),1),)))} | I17: {=IF(ISERROR(OFFSET(#REF!,SMALL(IF(#REF!=RM시즌체크판!C17,ROW(#REF!)-20),2),)),"",(OFFSET(#REF!,SMALL(IF(#REF!=RM시즌체크판!C17,ROW(#REF!)-20),2),)))} | J17: {=IF(ISERROR(OFFSET(#REF!,SMALL(IF(#REF!=RM시즌체크판!C17,ROW(#REF!)-20),3),)),"",(OFFSET(#REF!,SMALL(IF(#REF!=RM시즌체크판!C17,ROW(#REF!)-20),3),)))} | K17: {=IF(ISERROR(OFFSET(#REF!,SMALL(IF(#REF!=RM시즌체크판!C17,ROW(#REF!)-20),4),)),"",(OFFSET(#REF!,SMALL(IF(#REF!=RM시즌체크판!C17,ROW(#REF!)-20),4),)))} | L17: {=IF(ISERROR(OFFSET(#REF!,SMALL(IF(#REF!=RM시즌체크판!C17,ROW(#REF!)-20),5),)),"",(OFFSET(#REF!,SMALL(IF(#REF!=RM시즌체크판!C17,ROW(#REF!)-20),5),)))} | M17: {=IF(ISERROR(OFFSET(#REF!,SMALL(IF(#REF!=RM시즌체크판!C17,ROW(#REF!)-20),6),)),"",(OFFSET(#REF!,SMALL(IF(#REF!=RM시즌체크판!C17,ROW(#REF!)-20),6),)))} | N17: =IF(ISERROR(VLOOKUP(C17,모델촬영리스트!$C:$E,3,)),"",(VLOOKUP(C17,모델촬영리스트!$C:$E,3,))) | O17: =IF(ISERROR(VLOOKUP(C17,배너촬영리스트!$C:$E,3,)),"",(VLOOKUP(C17,배너촬영리스트!$C:$E,3,))) | P17: =IF(ISERROR(VLOOKUP(C17,배너촬영리스트!$C:$E,2,)),"",(VLOOKUP(C17,배너촬영리스트!$C:$E,2,)))
B18: =MID(C18,1,2) -> RM | C18: RMAS748RT6 | D18: =VLOOKUP(C18,#REF!,2,0) -> #REF! | E18: =VLOOKUP(C18,#REF!,4,0) -> #REF! | F18: =VLOOKUP(C18,#REF!,8,0) -> #REF! | G18: =IF(ISERROR(IF(VLOOKUP(C18,#REF!,2,0)>0,"등록","")),"",(IF(VLOOKUP(C18,#REF!,2,0)>0,"등록",""))) | H18: {=IF(ISERROR(OFFSET(#REF!,SMALL(IF(#REF!=RM시즌체크판!C18,ROW(#REF!)-20),1),)),"",(OFFSET(#REF!,SMALL(IF(#REF!=RM시즌체크판!C18,ROW(#REF!)-20),1),)))} | I18: {=IF(ISERROR(OFFSET(#REF!,SMALL(IF(#REF!=RM시즌체크판!C18,ROW(#REF!)-20),2),)),"",(OFFSET(#REF!,SMALL(IF(#REF!=RM시즌체크판!C18,ROW(#REF!)-20),2),)))} | J18: {=IF(ISERROR(OFFSET(#REF!,SMALL(IF(#REF!=RM시즌체크판!C18,ROW(#REF!)-20),3),)),"",(OFFSET(#REF!,SMALL(IF(#REF!=RM시즌체크판!C18,ROW(#REF!)-20),3),)))} | K18: {=IF(ISERROR(OFFSET(#REF!,SMALL(IF(#REF!=RM시즌체크판!C18,ROW(#REF!)-20),4),)),"",(OFFSET(#REF!,SMALL(IF(#REF!=RM시즌체크판!C18,ROW(#REF!)-20),4),)))} | L18: {=IF(ISERROR(OFFSET(#REF!,SMALL(IF(#REF!=RM시즌체크판!C18,ROW(#REF!)-20),5),)),"",(OFFSET(#REF!,SMALL(IF(#REF!=RM시즌체크판!C18,ROW(#REF!)-20),5),)))} | M18: {=IF(ISERROR(OFFSET(#REF!,SMALL(IF(#REF!=RM시즌체크판!C18,ROW(#REF!)-20),6),)),"",(OFFSET(#REF!,SMALL(IF(#REF!=RM시즌체크판!C18,ROW(#REF!)-20),6),)))} | N18: =IF(ISERROR(VLOOKUP(C18,모델촬영리스트!$C:$E,3,)),"",(VLOOKUP(C18,모델촬영리스트!$C:$E,3,))) | O18: =IF(ISERROR(VLOOKUP(C18,배너촬영리스트!$C:$E,3,)),"",(VLOOKUP(C18,배너촬영리스트!$C:$E,3,))) | P18: =IF(ISERROR(VLOOKUP(C18,배너촬영리스트!$C:$E,2,)),"",(VLOOKUP(C18,배너촬영리스트!$C:$E,2,)))
... B417: =MID(C417,1,2) -> RM | C417: RMYW74CRQ1 | D417: =VLOOKUP(C417,#REF!,2,0) -> #REF! | E417: =VLOOKUP(C417,#REF!,4,0) -> #REF! | F417: =VLOOKUP(C417,#REF!,8,0) -> #REF! | G417: =IF(ISERROR(IF(VLOOKUP(C417,#REF!,2,0)>0,"등록","")),"",(IF(VLOOKUP(C417,#REF!,2,0)>0,"등록",""))) | H417: {=IF(ISERROR(OFFSET(#REF!,SMALL(IF(#REF!=RM시즌체크판!C417,ROW(#REF!)-20),1),)),"",(OFFSET(#REF!,SMALL(IF(#REF!=RM시즌체크판!C417,ROW(#REF!)-20),1),)))} | I417: {=IF(ISERROR(OFFSET(#REF!,SMALL(IF(#REF!=RM시즌체크판!C417,ROW(#REF!)-20),2),)),"",(OFFSET(#REF!,SMALL(IF(#REF!=RM시즌체크판!C417,ROW(#REF!)-20),2),)))} | J417: {=IF(ISERROR(OFFSET(#REF!,SMALL(IF(#REF!=RM시즌체크판!C417,ROW(#REF!)-20),3),)),"",(OFFSET(#REF!,SMALL(IF(#REF!=RM시즌체크판!C417,ROW(#REF!)-20),3),)))} | K417: {=IF(ISERROR(OFFSET(#REF!,SMALL(IF(#REF!=RM시즌체크판!C417,ROW(#REF!)-20),4),)),"",(OFFSET(#REF!,SMALL(IF(#REF!=RM시즌체크판!C417,ROW(#REF!)-20),4),)))} | L417: {=IF(ISERROR(OFFSET(#REF!,SMALL(IF(#REF!=RM시즌체크판!C417,ROW(#REF!)-20),5),)),"",(OFFSET(#REF!,SMALL(IF(#REF!=RM시즌체크판!C417,ROW(#REF!)-20),5),)))} | M417: {=IF(ISERROR(OFFSET(#REF!,SMALL(IF(#REF!=RM시즌체크판!C417,ROW(#REF!)-20),6),)),"",(OFFSET(#REF!,SMALL(IF(#REF!=RM시즌체크판!C417,ROW(#REF!)-20),6),)))} | N417: =IF(ISERROR(VLOOKUP(C417,모델촬영리스트!$C:$E,3,)),"",(VLOOKUP(C417,모델촬영리스트!$C:$E,3,))) | O417: =IF(ISERROR(VLOOKUP(C417,배너촬영리스트!$C:$E,3,)),"",(VLOOKUP(C417,배너촬영리스트!$C:$E,3,))) | P417: =IF(ISERROR(VLOOKUP(C417,배너촬영리스트!$C:$E,2,)),"",(VLOOKUP(C417,배너촬영리스트!$C:$E,2,)))
B418: =MID(C418,1,2) | D418: =VLOOKUP(C418,#REF!,2,0) -> #REF! | E418: =VLOOKUP(C418,#REF!,4,0) -> #REF! | F418: =VLOOKUP(C418,#REF!,8,0) -> #REF! | G418: =IF(ISERROR(IF(VLOOKUP(C418,#REF!,2,0)>0,"등록","")),"",(IF(VLOOKUP(C418,#REF!,2,0)>0,"등록",""))) | H418: {=IF(ISERROR(OFFSET(#REF!,SMALL(IF(#REF!=RM시즌체크판!C418,ROW(#REF!)-20),1),)),"",(OFFSET(#REF!,SMALL(IF(#REF!=RM시즌체크판!C418,ROW(#REF!)-20),1),)))} | I418: {=IF(ISERROR(OFFSET(#REF!,SMALL(IF(#REF!=RM시즌체크판!C418,ROW(#REF!)-20),2),)),"",(OFFSET(#REF!,SMALL(IF(#REF!=RM시즌체크판!C418,ROW(#REF!)-20),2),)))} | J418: {=IF(ISERROR(OFFSET(#REF!,SMALL(IF(#REF!=RM시즌체크판!C418,ROW(#REF!)-20),3),)),"",(OFFSET(#REF!,SMALL(IF(#REF!=RM시즌체크판!C418,ROW(#REF!)-20),3),)))} | K418: {=IF(ISERROR(OFFSET(#REF!,SMALL(IF(#REF!=RM시즌체크판!C418,ROW(#REF!)-20),4),)),"",(OFFSET(#REF!,SMALL(IF(#REF!=RM시즌체크판!C418,ROW(#REF!)-20),4),)))} | L418: {=IF(ISERROR(OFFSET(#REF!,SMALL(IF(#REF!=RM시즌체크판!C418,ROW(#REF!)-20),5),)),"",(OFFSET(#REF!,SMALL(IF(#REF!=RM시즌체크판!C418,ROW(#REF!)-20),5),)))} | M418: {=IF(ISERROR(OFFSET(#REF!,SMALL(IF(#REF!=RM시즌체크판!C418,ROW(#REF!)-20),6),)),"",(OFFSET(#REF!,SMALL(IF(#REF!=RM시즌체크판!C418,ROW(#REF!)-20),6),)))} | N418: =IF(ISERROR(VLOOKUP(C418,모델촬영리스트!$C:$E,3,)),"",(VLOOKUP(C418,모델촬영리스트!$C:$E,3,))) | O418: =IF(ISERROR(VLOOKUP(C418,배너촬영리스트!$C:$E,3,)),"",(VLOOKUP(C418,배너촬영리스트!$C:$E,3,))) | P418: =IF(ISERROR(VLOOKUP(C418,배너촬영리스트!$C:$E,2,)),"",(VLOOKUP(C418,배너촬영리스트!$C:$E,2,)))
B419: =MID(C419,1,2) | D419: =VLOOKUP(C419,#REF!,2,0) -> #REF! | E419: =VLOOKUP(C419,#REF!,4,0) -> #REF! | F419: =VLOOKUP(C419,#REF!,8,0) -> #REF! | G419: =IF(ISERROR(IF(VLOOKUP(C419,#REF!,2,0)>0,"등록","")),"",(IF(VLOOKUP(C419,#REF!,2,0)>0,"등록",""))) | H419: {=IF(ISERROR(OFFSET(#REF!,SMALL(IF(#REF!=RM시즌체크판!C419,ROW(#REF!)-20),1),)),"",(OFFSET(#REF!,SMALL(IF(#REF!=RM시즌체크판!C419,ROW(#REF!)-20),1),)))} | I419: {=IF(ISERROR(OFFSET(#REF!,SMALL(IF(#REF!=RM시즌체크판!C419,ROW(#REF!)-20),2),)),"",(OFFSET(#REF!,SMALL(IF(#REF!=RM시즌체크판!C419,ROW(#REF!)-20),2),)))} | J419: {=IF(ISERROR(OFFSET(#REF!,SMALL(IF(#REF!=RM시즌체크판!C419,ROW(#REF!)-20),3),)),"",(OFFSET(#REF!,SMALL(IF(#REF!=RM시즌체크판!C419,ROW(#REF!)-20),3),)))} | K419: {=IF(ISERROR(OFFSET(#REF!,SMALL(IF(#REF!=RM시즌체크판!C419,ROW(#REF!)-20),4),)),"",(OFFSET(#REF!,SMALL(IF(#REF!=RM시즌체크판!C419,ROW(#REF!)-20),4),)))} | L419: {=IF(ISERROR(OFFSET(#REF!,SMALL(IF(#REF!=RM시즌체크판!C419,ROW(#REF!)-20),5),)),"",(OFFSET(#REF!,SMALL(IF(#REF!=RM시즌체크판!C419,ROW(#REF!)-20),5),)))} | M419: {=IF(ISERROR(OFFSET(#REF!,SMALL(IF(#REF!=RM시즌체크판!C419,ROW(#REF!)-20),6),)),"",(OFFSET(#REF!,SMALL(IF(#REF!=RM시즌체크판!C419,ROW(#REF!)-20),6),)))} | N419: =IF(ISERROR(VLOOKUP(C419,모델촬영리스트!$C:$E,3,)),"",(VLOOKUP(C419,모델촬영리스트!$C:$E,3,))) | O419: =IF(ISERROR(VLOOKUP(C419,배너촬영리스트!$C:$E,3,)),"",(VLOOKUP(C419,배너촬영리스트!$C:$E,3,))) | P419: =IF(ISERROR(VLOOKUP(C419,배너촬영리스트!$C:$E,2,)),"",(VLOOKUP(C419,배너촬영리스트!$C:$E,2,)))
B420: =MID(C420,1,2) | D420: =VLOOKUP(C420,#REF!,2,0) -> #REF! | E420: =VLOOKUP(C420,#REF!,4,0) -> #REF! | F420: =VLOOKUP(C420,#REF!,8,0) -> #REF! | G420: =IF(ISERROR(IF(VLOOKUP(C420,#REF!,2,0)>0,"등록","")),"",(IF(VLOOKUP(C420,#REF!,2,0)>0,"등록",""))) | H420: {=IF(ISERROR(OFFSET(#REF!,SMALL(IF(#REF!=RM시즌체크판!C420,ROW(#REF!)-20),1),)),"",(OFFSET(#REF!,SMALL(IF(#REF!=RM시즌체크판!C420,ROW(#REF!)-20),1),)))} | I420: {=IF(ISERROR(OFFSET(#REF!,SMALL(IF(#REF!=RM시즌체크판!C420,ROW(#REF!)-20),2),)),"",(OFFSET(#REF!,SMALL(IF(#REF!=RM시즌체크판!C420,ROW(#REF!)-20),2),)))} | J420: {=IF(ISERROR(OFFSET(#REF!,SMALL(IF(#REF!=RM시즌체크판!C420,ROW(#REF!)-20),3),)),"",(OFFSET(#REF!,SMALL(IF(#REF!=RM시즌체크판!C420,ROW(#REF!)-20),3),)))} | K420: {=IF(ISERROR(OFFSET(#REF!,SMALL(IF(#REF!=RM시즌체크판!C420,ROW(#REF!)-20),4),)),"",(OFFSET(#REF!,SMALL(IF(#REF!=RM시즌체크판!C420,ROW(#REF!)-20),4),)))} | L420: {=IF(ISERROR(OFFSET(#REF!,SMALL(IF(#REF!=RM시즌체크판!C420,ROW(#REF!)-20),5),)),"",(OFFSET(#REF!,SMALL(IF(#REF!=RM시즌체크판!C420,ROW(#REF!)-20),5),)))} | M420: {=IF(ISERROR(OFFSET(#REF!,SMALL(IF(#REF!=RM시즌체크판!C420,ROW(#REF!)-20),6),)),"",(OFFSET(#REF!,SMALL(IF(#REF!=RM시즌체크판!C420,ROW(#REF!)-20),6),)))} | N420: =IF(ISERROR(VLOOKUP(C420,모델촬영리스트!$C:$E,3,)),"",(VLOOKUP(C420,모델촬영리스트!$C:$E,3,))) | O420: =IF(ISERROR(VLOOKUP(C420,배너촬영리스트!$C:$E,3,)),"",(VLOOKUP(C420,배너촬영리스트!$C:$E,3,))) | P420: =IF(ISERROR(VLOOKUP(C420,배너촬영리스트!$C:$E,2,)),"",(VLOOKUP(C420,배너촬영리스트!$C:$E,2,)))
B421: =MID(C421,1,2) | D421: =VLOOKUP(C421,#REF!,2,0) -> #REF! | E421: =VLOOKUP(C421,#REF!,4,0) -> #REF! | F421: =VLOOKUP(C421,#REF!,8,0) -> #REF! | G421: =IF(ISERROR(IF(VLOOKUP(C421,#REF!,2,0)>0,"등록","")),"",(IF(VLOOKUP(C421,#REF!,2,0)>0,"등록",""))) | H421: {=IF(ISERROR(OFFSET(#REF!,SMALL(IF(#REF!=RM시즌체크판!C421,ROW(#REF!)-20),1),)),"",(OFFSET(#REF!,SMALL(IF(#REF!=RM시즌체크판!C421,ROW(#REF!)-20),1),)))} | I421: {=IF(ISERROR(OFFSET(#REF!,SMALL(IF(#REF!=RM시즌체크판!C421,ROW(#REF!)-20),2),)),"",(OFFSET(#REF!,SMALL(IF(#REF!=RM시즌체크판!C421,ROW(#REF!)-20),2),)))} | J421: {=IF(ISERROR(OFFSET(#REF!,SMALL(IF(#REF!=RM시즌체크판!C421,ROW(#REF!)-20),3),)),"",(OFFSET(#REF!,SMALL(IF(#REF!=RM시즌체크판!C421,ROW(#REF!)-20),3),)))} | K421: {=IF(ISERROR(OFFSET(#REF!,SMALL(IF(#REF!=RM시즌체크판!C421,ROW(#REF!)-20),4),)),"",(OFFSET(#REF!,SMALL(IF(#REF!=RM시즌체크판!C421,ROW(#REF!)-20),4),)))} | L421: {=IF(ISERROR(OFFSET(#REF!,SMALL(IF(#REF!=RM시즌체크판!C421,ROW(#REF!)-20),5),)),"",(OFFSET(#REF!,SMALL(IF(#REF!=RM시즌체크판!C421,ROW(#REF!)-20),5),)))} | M421: {=IF(ISERROR(OFFSET(#REF!,SMALL(IF(#REF!=RM시즌체크판!C421,ROW(#REF!)-20),6),)),"",(OFFSET(#REF!,SMALL(IF(#REF!=RM시즌체크판!C421,ROW(#REF!)-20),6),)))} | N421: =IF(ISERROR(VLOOKUP(C421,모델촬영리스트!$C:$E,3,)),"",(VLOOKUP(C421,모델촬영리스트!$C:$E,3,))) | O421: =IF(ISERROR(VLOOKUP(C421,배너촬영리스트!$C:$E,3,)),"",(VLOOKUP(C421,배너촬영리스트!$C:$E,3,))) | P421: =IF(ISERROR(VLOOKUP(C421,배너촬영리스트!$C:$E,2,)),"",(VLOOKUP(C421,배너촬영리스트!$C:$E,2,)))
B422: =MID(C422,1,2) | D422: =VLOOKUP(C422,#REF!,2,0) -> #REF! | E422: =VLOOKUP(C422,#REF!,4,0) -> #REF! | F422: =VLOOKUP(C422,#REF!,8,0) -> #REF! | G422: =IF(ISERROR(IF(VLOOKUP(C422,#REF!,2,0)>0,"등록","")),"",(IF(VLOOKUP(C422,#REF!,2,0)>0,"등록",""))) | H422: {=IF(ISERROR(OFFSET(#REF!,SMALL(IF(#REF!=RM시즌체크판!C422,ROW(#REF!)-20),1),)),"",(OFFSET(#REF!,SMALL(IF(#REF!=RM시즌체크판!C422,ROW(#REF!)-20),1),)))} | I422: {=IF(ISERROR(OFFSET(#REF!,SMALL(IF(#REF!=RM시즌체크판!C422,ROW(#REF!)-20),2),)),"",(OFFSET(#REF!,SMALL(IF(#REF!=RM시즌체크판!C422,ROW(#REF!)-20),2),)))} | J422: {=IF(ISERROR(OFFSET(#REF!,SMALL(IF(#REF!=RM시즌체크판!C422,ROW(#REF!)-20),3),)),"",(OFFSET(#REF!,SMALL(IF(#REF!=RM시즌체크판!C422,ROW(#REF!)-20),3),)))} | K422: {=IF(ISERROR(OFFSET(#REF!,SMALL(IF(#REF!=RM시즌체크판!C422,ROW(#REF!)-20),4),)),"",(OFFSET(#REF!,SMALL(IF(#REF!=RM시즌체크판!C422,ROW(#REF!)-20),4),)))} | L422: {=IF(ISERROR(OFFSET(#REF!,SMALL(IF(#REF!=RM시즌체크판!C422,ROW(#REF!)-20),5),)),"",(OFFSET(#REF!,SMALL(IF(#REF!=RM시즌체크판!C422,ROW(#REF!)-20),5),)))} | M422: {=IF(ISERROR(OFFSET(#REF!,SMALL(IF(#REF!=RM시즌체크판!C422,ROW(#REF!)-20),6),)),"",(OFFSET(#REF!,SMALL(IF(#REF!=RM시즌체크판!C422,ROW(#REF!)-20),6),)))} | N422: =IF(ISERROR(VLOOKUP(C422,모델촬영리스트!$C:$E,3,)),"",(VLOOKUP(C422,모델촬영리스트!$C:$E,3,))) | O422: =IF(ISERROR(VLOOKUP(C422,배너촬영리스트!$C:$E,3,)),"",(VLOOKUP(C422,배너촬영리스트!$C:$E,3,))) | P422: =IF(ISERROR(VLOOKUP(C422,배너촬영리스트!$C:$E,2,)),"",(VLOOKUP(C422,배너촬영리스트!$C:$E,2,)))
B423: =MID(C423,1,2) | D423: =VLOOKUP(C423,#REF!,2,0) -> #REF! | E423: =VLOOKUP(C423,#REF!,4,0) -> #REF! | F423: =VLOOKUP(C423,#REF!,8,0) -> #REF! | G423: =IF(ISERROR(IF(VLOOKUP(C423,#REF!,2,0)>0,"등록","")),"",(IF(VLOOKUP(C423,#REF!,2,0)>0,"등록",""))) | H423: {=IF(ISERROR(OFFSET(#REF!,SMALL(IF(#REF!=RM시즌체크판!C423,ROW(#REF!)-20),1),)),"",(OFFSET(#REF!,SMALL(IF(#REF!=RM시즌체크판!C423,ROW(#REF!)-20),1),)))} | I423: {=IF(ISERROR(OFFSET(#REF!,SMALL(IF(#REF!=RM시즌체크판!C423,ROW(#REF!)-20),2),)),"",(OFFSET(#REF!,SMALL(IF(#REF!=RM시즌체크판!C423,ROW(#REF!)-20),2),)))} | J423: {=IF(ISERROR(OFFSET(#REF!,SMALL(IF(#REF!=RM시즌체크판!C423,ROW(#REF!)-20),3),)),"",(OFFSET(#REF!,SMALL(IF(#REF!=RM시즌체크판!C423,ROW(#REF!)-20),3),)))} | K423: {=IF(ISERROR(OFFSET(#REF!,SMALL(IF(#REF!=RM시즌체크판!C423,ROW(#REF!)-20),4),)),"",(OFFSET(#REF!,SMALL(IF(#REF!=RM시즌체크판!C423,ROW(#REF!)-20),4),)))} | L423: {=IF(ISERROR(OFFSET(#REF!,SMALL(IF(#REF!=RM시즌체크판!C423,ROW(#REF!)-20),5),)),"",(OFFSET(#REF!,SMALL(IF(#REF!=RM시즌체크판!C423,ROW(#REF!)-20),5),)))} | M423: {=IF(ISERROR(OFFSET(#REF!,SMALL(IF(#REF!=RM시즌체크판!C423,ROW(#REF!)-20),6),)),"",(OFFSET(#REF!,SMALL(IF(#REF!=RM시즌체크판!C423,ROW(#REF!)-20),6),)))} | N423: =IF(ISERROR(VLOOKUP(C423,모델촬영리스트!$C:$E,3,)),"",(VLOOKUP(C423,모델촬영리스트!$C:$E,3,))) | O423: =IF(ISERROR(VLOOKUP(C423,배너촬영리스트!$C:$E,3,)),"",(VLOOKUP(C423,배너촬영리스트!$C:$E,3,))) | P423: =IF(ISERROR(VLOOKUP(C423,배너촬영리스트!$C:$E,2,)),"",(VLOOKUP(C423,배너촬영리스트!$C:$E,2,)))
B424: =MID(C424,1,2) | D424: =VLOOKUP(C424,#REF!,2,0) -> #REF! | E424: =VLOOKUP(C424,#REF!,4,0) -> #REF! | F424: =VLOOKUP(C424,#REF!,8,0) -> #REF! | G424: =IF(ISERROR(IF(VLOOKUP(C424,#REF!,2,0)>0,"등록","")),"",(IF(VLOOKUP(C424,#REF!,2,0)>0,"등록",""))) | H424: {=IF(ISERROR(OFFSET(#REF!,SMALL(IF(#REF!=RM시즌체크판!C424,ROW(#REF!)-20),1),)),"",(OFFSET(#REF!,SMALL(IF(#REF!=RM시즌체크판!C424,ROW(#REF!)-20),1),)))} | I424: {=IF(ISERROR(OFFSET(#REF!,SMALL(IF(#REF!=RM시즌체크판!C424,ROW(#REF!)-20),2),)),"",(OFFSET(#REF!,SMALL(IF(#REF!=RM시즌체크판!C424,ROW(#REF!)-20),2),)))} | J424: {=IF(ISERROR(OFFSET(#REF!,SMALL(IF(#REF!=RM시즌체크판!C424,ROW(#REF!)-20),3),)),"",(OFFSET(#REF!,SMALL(IF(#REF!=RM시즌체크판!C424,ROW(#REF!)-20),3),)))} | K424: {=IF(ISERROR(OFFSET(#REF!,SMALL(IF(#REF!=RM시즌체크판!C424,ROW(#REF!)-20),4),)),"",(OFFSET(#REF!,SMALL(IF(#REF!=RM시즌체크판!C424,ROW(#REF!)-20),4),)))} | L424: {=IF(ISERROR(OFFSET(#REF!,SMALL(IF(#REF!=RM시즌체크판!C424,ROW(#REF!)-20),5),)),"",(OFFSET(#REF!,SMALL(IF(#REF!=RM시즌체크판!C424,ROW(#REF!)-20),5),)))} | M424: {=IF(ISERROR(OFFSET(#REF!,SMALL(IF(#REF!=RM시즌체크판!C424,ROW(#REF!)-20),6),)),"",(OFFSET(#REF!,SMALL(IF(#REF!=RM시즌체크판!C424,ROW(#REF!)-20),6),)))} | N424: =IF(ISERROR(VLOOKUP(C424,모델촬영리스트!$C:$E,3,)),"",(VLOOKUP(C424,모델촬영리스트!$C:$E,3,))) | O424: =IF(ISERROR(VLOOKUP(C424,배너촬영리스트!$C:$E,3,)),"",(VLOOKUP(C424,배너촬영리스트!$C:$E,3,))) | P424: =IF(ISERROR(VLOOKUP(C424,배너촬영리스트!$C:$E,2,)),"",(VLOOKUP(C424,배너촬영리스트!$C:$E,2,)))
B425: =MID(C425,1,2) | D425: =VLOOKUP(C425,#REF!,2,0) -> #REF! | E425: =VLOOKUP(C425,#REF!,4,0) -> #REF! | F425: =VLOOKUP(C425,#REF!,8,0) -> #REF! | G425: =IF(ISERROR(IF(VLOOKUP(C425,#REF!,2,0)>0,"등록","")),"",(IF(VLOOKUP(C425,#REF!,2,0)>0,"등록",""))) | H425: {=IF(ISERROR(OFFSET(#REF!,SMALL(IF(#REF!=RM시즌체크판!C425,ROW(#REF!)-20),1),)),"",(OFFSET(#REF!,SMALL(IF(#REF!=RM시즌체크판!C425,ROW(#REF!)-20),1),)))} | I425: {=IF(ISERROR(OFFSET(#REF!,SMALL(IF(#REF!=RM시즌체크판!C425,ROW(#REF!)-20),2),)),"",(OFFSET(#REF!,SMALL(IF(#REF!=RM시즌체크판!C425,ROW(#REF!)-20),2),)))} | J425: {=IF(ISERROR(OFFSET(#REF!,SMALL(IF(#REF!=RM시즌체크판!C425,ROW(#REF!)-20),3),)),"",(OFFSET(#REF!,SMALL(IF(#REF!=RM시즌체크판!C425,ROW(#REF!)-20),3),)))} | K425: {=IF(ISERROR(OFFSET(#REF!,SMALL(IF(#REF!=RM시즌체크판!C425,ROW(#REF!)-20),4),)),"",(OFFSET(#REF!,SMALL(IF(#REF!=RM시즌체크판!C425,ROW(#REF!)-20),4),)))} | L425: {=IF(ISERROR(OFFSET(#REF!,SMALL(IF(#REF!=RM시즌체크판!C425,ROW(#REF!)-20),5),)),"",(OFFSET(#REF!,SMALL(IF(#REF!=RM시즌체크판!C425,ROW(#REF!)-20),5),)))} | M425: {=IF(ISERROR(OFFSET(#REF!,SMALL(IF(#REF!=RM시즌체크판!C425,ROW(#REF!)-20),6),)),"",(OFFSET(#REF!,SMALL(IF(#REF!=RM시즌체크판!C425,ROW(#REF!)-20),6),)))} | N425: =IF(ISERROR(VLOOKUP(C425,모델촬영리스트!$C:$E,3,)),"",(VLOOKUP(C425,모델촬영리스트!$C:$E,3,))) | O425: =IF(ISERROR(VLOOKUP(C425,배너촬영리스트!$C:$E,3,)),"",(VLOOKUP(C425,배너촬영리스트!$C:$E,3,))) | P425: =IF(ISERROR(VLOOKUP(C425,배너촬영리스트!$C:$E,2,)),"",(VLOOKUP(C425,배너촬영리스트!$C:$E,2,)))

Sheet WH등록판
B1: 스튜디오 전표일자 | C1: 포토인계일 | E1: 리터칭완료일 | F1: 포토 | G1: 상품군 | H1: 시즌 | I1: 월 | J1: 브랜드 | K1: 스타일코드 | L1: 스타일명 | M1: 입고유형 | N1: 입고 | O1: 완료 | P1: 정판가 | Q1: 최초출고일 | R1: 매장출고 (이스퀘어강남) | S1: 공홈 등록일 | T1: 입고 차이 | U1: 구현 차이 | V1: 공홈 등록여부 | W1: 모델컷 촬영일 | X1: 모델컷 업로드일 | Y1: 모델컷 등록일 | Z1: 상품컷 (컬러별)_단품촬영 후 컬러링 표기로 체크할 것! | AF1: 착장컷 | AG1: 배너컷 | AH1: 배너촬영일 | AI1: 공홈등록 소요일 (공홈등록일-리터칭완료일) | AJ1: 포토소요일
B2: 2025-11-28 | C2: 45992 | D2: 45993 | E2: 45995 | F2: 3 | G2: A | H2: G1 | I2: 1 | J2: WH | K2: WHACG1111A | L2: Steve Ball Cap | M2: 물류 | N2: 입고 | O2: 완료 | P2: 29900 | Q2: 2025-11-28 | R2: 45999 | S2: 45996 | T2: 7 | U2: -3 | V2: 등록 | Z2: (19)Black | AA2: (35)Beige | AB2: (36)Light Beige | AC2: (39)Ivory | AD2: (59)Navy | AI2: 1 | AJ2: 3 | AK2: G
B3: 2025-11-27 | C3: 45989 | D3: 45989 | E3: 45989 | F3: 0 | G3: A | H3: G1 | I3: 1 | J3: WH | K3: WHACG1112A | L3: Steve Head Embroidery Washed Ball Cap | M3: 물류 | N3: 입고 | O3: 완료 | P3: 39900 | Q3: 2025-11-27 | R3: 45999 | S3: 45992 | T3: 4 | U3: -7 | V3: 등록 | Z3: (17)Dark Gray | AA3: (26)Light Pink | AB3: (51)Light Blue | AI3: 3 | AJ3: 0 | AK3: G
B4: 2025-12-18 | C4: 46010 | D4: 46015 | E4: 46020 | F4: 10 | G4: A | H4: G1 | I4: 1 | J4: WH | K4: WHAYG1111A | L4: Steve Embroidery Socks | M4: 물류 | N4: 입고 | O4: 완료 | P4: 9900 | Q4: 2025-12-18 | R4: 46013 | S4: 46021 | T4: 12 | U4: 8 | V4: 등록 | Z4: (19)Black | AA4: (33)Oatmeal Melange | AB4: (35)Beige | AC4: (39)Ivory | AD4: (AC)Melange Gray | AI4: 1 | AJ4: 10 | AK4: G
B5: 2025-12-18 | C5: 46010 | D5: 46015 | E5: 46020 | F5: 10 | G5: A | H5: G1 | I5: 1 | J5: WH | K5: WHAYG1112A | L5: [3PACK]Steve Ankle Socks | M5: 물류 | N5: 입고 | O5: 완료 | P5: 19900 | Q5: 2025-12-18 | R5: 46009 | S5: 46021 | T5: 12 | U5: 12 | V5: 등록 | Z5: (39)Ivory | AA5: (85)Brown | AI5: 1 | AJ5: 10 | AK5: G
B6: 2025-12-18 | C6: 46010 | D6: 46015 | E6: 46020 | F6: 10 | G6: A | H6: G1 | I6: 1 | J6: WH | K6: WHAYG1113A | L6: [4PACK]Steve Fake Socks | M6: 물류 | N6: 입고 | O6: 완료 | P6: 19900 | Q6: 2025-12-18 | R6: 46009 | S6: 46021 | T6: 12 | U6: 12 | V6: 등록 | Z6: (25)Pink | AA6: (39)Ivory | AI6: 1 | AJ6: 10 | AK6: G
B7: 2025-12-18 | C7: 46010 | D7: 46015 | E7: 46020 | F7: 10 | G7: A | H7: G1 | I7: 1 | J7: WH | K7: WHAYG1121A | L7: [2PACK]Steve Dot Socks | M7: 물류 | N7: 입고 | O7: 완료 | P7: 19900 | Q7: 2025-12-18 | R7: 46009 | S7: 46021 | T7: 12 | U7: 12 | V7: 등록 | Z7: (99)Mix | AI7: 1 | AJ7: 10 | AK7: G
B8: 2025-12-4 | C8: 45996 | D8: 46014 | E8: 46015 | F8: 19 | G8: A | H8: G1 | I8: 1 | J8: WH | K8: WHBGG1111A | L8: Steve Nylon Mini Cross Bag | M8: 물류 | N8: 입고 | O8: 완료 | P8: 39900 | Q8: 2025-12-04 | R8: 46002 | S8: 46020 | T8: 25 | U8: 18 | V8: 등록 | Z8: (19)Black | AA8: (25)Pink | AB8: (35)Beige | AC8: (39)Ivory | AI8: 5 | AJ8: 19 | AK8: G
B9: 2025-11-27 | C9: 45989 | D9: 45989 | E9: 45992 | F9: 3 | G9: A | H9: G1 | I9: 1 | J9: WH | K9: WHBGG1151A | L9: Steve Flap Mini Backpack[B] | M9: 물류 | N9: 입고 | O9: 완료 | P9: 49900 | Q9: 2025-11-27 | S9: 45993 | T9: 5 | V9: 등록 | Z9: (19)Black | AA9: (25)Pink | AB9: (35)Beige | AI9: 1 | AJ9: 3 | AK9: G
B10: 2025-12-15 | C10: 46007 | D10: 46021 | E10: 46021 | F10: 14 | G10: F | H10: G1 | I10: 1 | J10: WH | K10: WHCKG1111F | L10: Steve R-neck Cardigan | M10: 물류 | N10: 입고 | O10: 완료 | P10: 49900 | Q10: 2025-12-15 | R10: 46006 | S10: 46024 | T10: 18 | U10: 18 | V10: 등록 | Z10: (19)Black | AA10: (20)Red | AB10: (39)Ivory | AC10: (59)Navy | AI10: 3 | AJ10: 14 | AK10: G
B11: 2025-12-3 | C11: 45995 | D11: 45999 | E11: 46001 | F11: 6 | G11: F | H11: G1 | I11: 2 | J11: WH | K11: WHCKG1215F | L11: Steve High Gauge Wool Cable Cardigan | M11: 물류 | N11: 입고 | O11: 완료 | P11: 49900 | Q11: 2025-12-02 | R11: 45994 | S11: 46002 | T11: 9 | U11: 8 | V11: 등록 | Z11: (19)Black | AA11: (33)Oatmeal Melange | AB11: (35)Beige | AC11: (50)Blue | AD11: (AC)Melange Gray | AI11: 1 | AJ11: 6 | AK11: G
G12: F | H12: G1 | I12: 1 | J12: WH | K12: WHJJG1111F | L12: Steve Quilting Jacket | P12: 0 | Q12: # | Z12: (19)Black | AK12: G
B13: 2025-12-2 | C13: 45994 | D13: 45995 | E13: 45996 | F13: 2 | G13: F | H13: G1 | I13: 1 | J13: WH | K13: WHJJG1112F | L13: Steve Reversible Quilting Jacket | M13: 물류 | N13: 입고 | O13: 완료 | P13: 79900 | Q13: 2025-12-02 | R13: 46006 | S13: 46000 | T13: 7 | U13: -6 | V13: 등록 | W13: 2025. 12. 15 | X13: 2025. 12. 22 | Y13: 2025. 12. 30 | Z13: (19)Black | AA13: (39)Ivory | AB13: (51)Light Blue | AI13: 4 | AJ13: 2 | AK13: G
B14: 2025-12-8 | C14: 46000 | D14: 46008 | E14: 46008 | F14: 8 | G14: F | H14: G1 | I14: 1 | J14: WH | K14: WHJJG1115F | L14: Reversible Dumble Jumper(F) | M14: 물류 | N14: 입고 | O14: 완료 | P14: 89900 | Q14: 2025-12-08 | R14: 46001 | S14: 46009 | T14: 10 | U14: 8 | V14: 등록 | Z14: (26)Light Pink | AA14: (85)Brown | AI14: 1 | AJ14: 8 | AK14: G
B15: 2026-1-20 | C15: 46043 | D15: 46043 | E15: 46044 | F15: 1 | G15: U | H15: G1 | I15: 1 | J15: WH | K15: WHJJG1121U | L15: USA Reversible Warm-Up Jacket | M15: 물류 | N15: 입고 | O15: 완료 | P15: 99900 | Q15: # | Z15: (59)Navy | AA15: (62)Hunter | AJ15: 1 | AK15: G
B16: 2026-1-8 | C16: 46031 | D16: 46048 | E16: 46048 | F16: 17 | G16: F | H16: G1 | I16: 1 | J16: WH | K16: WHJPG1112F | L16: Detachable Collar Quilted Jacket(F) | M16: 물류 | N16: 입고 | O16: 완료 | P16: 99900 | Q16: 2026-01-08 | R16: 46030 | Z16: (19)Black | AA16: (39)Ivory | AK16: G
G17: F | H17: G1 | I17: 1 | J17: WH | K17: WHJPG1115F | L17: Short Puffer Padding | P17: 0 | Q17: # | Z17: (19)Black | AK17: G
G18: U | H18: G1 | I18: 1 | J18: WH | K18: WHJPG1191U | L18: Light Padded Jacket | P18: 0 | Q18: # | Z18: (16)Light Gray | AK18: G
B19: 2025-12-24 | C19: 46017 | D19: 46035 | E19: 46035 | F19: 18 | G19: U | H19: G1 | I19: 1 | J19: WH | K19: WHJPG1196U | L19: Light Hooded Reversible Jacket | M19: 물류 | N19: 입고 | O19: 파샬 | P19: 99900 | Q19: 2025-12-24 | R19: 46015 | Z19: (19)Black | AA19: (39)Ivory | AB19: (91)Silver | AK19: G
B20: 2025-12-26 | C20: 46020 | D20: 46030 | E20: 46036 | F20: 16 | G20: F | H20: G1 | I20: 1 | J20: WH | K20: WHKAG1114F | L20: Steve V-neck Cable Sweater | M20: 물류 | N20: 입고 | O20: 완료 | P20: 49900 | Q20: 2025-12-26 | R20: 46017 | Z20: (10)White | AA20: (19)Black | AB20: (25)Pink | AC20: (AC)Melange Gray | AK20: G
B21: 2025-12-16 | C21: 46008 | D21: 46027 | E21: 46028 | F21: 20 | G21: M | H21: G1 | I21: 1 | J21: WH | K21: WHKAG1121M | L21: Steve Cable Sweater(M) | M21: 물류 | N21: 입고 | O21: 완료 | P21: 59900 | Q21: 2025-12-16 | R21: 46007 | S21: 46030 | T21: 23 | U21: 23 | V21: 등록 | Z21: (39)Ivory | AA21: (51)Light Blue | AB21: (59)Navy | AC21: (AC)Melange Gray | AI21: 2 | AJ21: 20 | AK21: G
B22: 2025-12-8 | C22: 46000 | D22: 46002 | E22: 46006 | F22: 6 | G22: F | H22: G1 | I22: 1 | J22: WH | K22: WHKAG1191F | L22: Folded Off-Shoulder Pullover | M22: 물류 | N22: 입고 | O22: 완료 | P22: 59900 | Q22: 2025-12-08 | R22: 45999 | S22: 46009 | T22: 10 | U22: 10 | V22: 등록 | Z22: (15)Gray | AA22: (39)Ivory | AI22: 3 | AJ22: 6 | AK22: G
B23: 2025-12-4 | C23: 45996 | D23: 46002 | E23: 46006 | F23: 10 | G23: U | H23: G1 | I23: 2 | J23: WH | K23: WHKAG1292U | L23: American Flag Intarsia Pullover | M23: 물류 | N23: 입고 | O23: 완료 | P23: 69900 | Q23: 2025-12-04 | R23: 45995 | S23: 46009 | T23: 14 | U23: 14 | V23: 등록 | Z23: (39)Ivory | AA23: (59)Navy | AI23: 3 | AJ23: 10 | AK23: G
B24: 2025-12-9 | C24: 46001 | D24: 46002 | E24: 46006 | F24: 5 | G24: U | H24: G1 | I24: 2 | J24: WH | K24: WHMHG1211U | L24: Steve Hoodie | M24: 물류 | N24: 입고 | O24: 완료 | P24: 49900 | Q24: 2025-12-09 | R24: 46001 | S24: 46009 | T24: 9 | U24: 8 | V24: 등록 | Z24: (33)Oatmeal Melange | AA24: (60)Charcoal | AI24: 3 | AJ24: 5 | AK24: G
B25: 2025-11-28 | C25: 45992 | D25: 45993 | E25: 45994 | F25: 2 | G25: U | H25: G1 | I25: 2 | J25: WH | K25: WHMWG1211U | L25: Steve Sweatshirt | M25: 물류 | N25: 입고 | O25: 완료 | P25: 39900 | Q25: 2025-11-28 | R25: 45992 | S25: 45995 | T25: 6 | U25: 3 | V25: 등록 | W25: 2025. 12. 8 | X25: 2025. 12. 15 | Y25: 2025. 12. 15 | Z25: (26)Light Pink | AA25: (39)Ivory | AB25: (59)Navy | AC25: (AA)Light Melange Gr | AI25: 1 | AJ25: 2 | AK25: G
B26: 2025-11-13 | C26: 45978 | D26: 45978 | E26: 45979 | F26: 1 | G26: F | H26: G1 | I26: 1 | J26: WH | K26: WHMZG1111F | L26: Patch Crop Hood Zip-up | M26: 물류 | N26: 입고 | O26: 완료 | P26: 69900 | Q26: 2025-11-13 | R26: 45993 | S26: 45979 | T26: 5 | U26: -14 | V26: 등록 | Z26: (39)Ivory | AA26: (59)Navy | AB26: (85)Brown | AC26: (AA)Light Melange Gr | AI26: 0 | AJ26: 1 | AK26: G
B27: 2025-12-3 | C27: 45995 | D27: 45995 | E27: 45996 | F27: 1 | G27: U | H27: G1 | I27: 1 | J27: WH | K27: WHMZG1111U | L27: Signature Patch Hood Zip-up | M27: 물류 | N27: 입고 | O27: 완료 | P27: 69900 | Q27: 2025-12-03 | R27: 46008 | S27: 46000 | T27: 6 | U27: -8 | V27: 등록 | W27: 2025. 12. 15 | X27: 2025. 12. 22 | Y27: 2025. 12. 30 | Z27: (39)Ivory | AA27: (59)Navy | AB27: (AA)Light Melange Gr | AC27: (AC)Melange Gray | AI27: 4 | AJ27: 1 | AK27: G
B28: 2025-11-4 | C28: 45966 | D28: 45966 | E28: 45968 | F28: 2 | G28: U | H28: G1 | I28: 1 | J28: WH | K28: WHMZG1112U | L28: Signature Patch Hood Zip-up(Colorblock) | M28: 물류 | N28: 입고 | O28: 파샬 | P28: 69900 | Q28: 2025-11-04 | R28: 46024 | S28: 45968 | T28: 3 | U28: -56 | V28: 등록 | W28: 2025. 12. 8 | X28: 2025. 12. 15 | Y28: 2025. 12. 15 | Z28: (19)Black | AA28: (29)Burgundy | AB28: (59)Navy | AI28: 0 | AJ28: 2 | AK28: G
B29: 2025-11-13 | C29: 45978 | D29: 45978 | E29: 45979 | F29: 1 | G29: F | H29: G1 | I29: 1 | J29: WH | K29: WHTMG1111F | L29: Patch Wide Pants | M29: 물류 | N29: 입고 | O29: 완료 | P29: 49900 | Q29: 2025-11-13 | R29: 46010 | S29: 45979 | T29: 5 | U29: -31 | V29: 등록 | Z29: (39)Ivory | AA29: (59)Navy | AB29: (AA)Light Melange Gr | AI29: 0 | AJ29: 1 | AK29: G
B30: 2025-12-3 | C30: 45995 | D30: 45996 | E30: 46000 | F30: 5 | G30: U | H30: G1 | I30: 1 | J30: WH | K30: WHTMG1111U | L30: Signature Patch Wide Pants | M30: 물류 | N30: 입고 | O30: 완료 | P30: 49900 | Q30: 2025-12-03 | R30: 46009 | S30: 46001 | T30: 7 | U30: -8 | V30: 등록 | Z30: (59)Navy | AA30: (AC)Melange Gray | AI30: 1 | AJ30: 5 | AK30: G
G31: U | H31: G1 | I31: 1 | J31: WH | K31: WHVWG1111U | L31: Steve Padding Vest | P31: 0 | Q31: # | Z31: (19)Black | AK31: G
B32: 2025-12-24 | C32: 46017 | D32: 46038 | E32: 46038 | F32: 21 | G32: A | H32: G2 | I32: 2 | J32: WH | K32: WHACG2221A | L32: Steve Denim Ball Cap | M32: 물류 | N32: 입고 | O32: 완료 | P32: 39900 | Q32: 2025-12-24 | R32: 46027 | Z32: (56)Light Indigo | AA32: (57)Dark Indigo | AK32: G
B33: 2025-11-27 | C33: 45989 | D33: 45989 | E33: 45992 | F33: 3 | G33: A | H33: G2 | I33: 2 | J33: WH | K33: WHACG2222A | L33: USA Embroidery Ball Cap | M33: 물류 | N33: 입고 | O33: 완료 | P33: 39900 | Q33: 2025-11-27 | R33: 45999 | S33: 45993 | T33: 5 | U33: -6 | V33: 등록 | Z33: (20)Red | AA33: (39)Ivory | AB33: (59)Navy | AI33: 1 | AJ33: 3 | AK33: G
B34: 2025-12-24 | C34: 46017 | D34: 46038 | E34: 46038 | F34: 21 | G34: A | H34: G2 | I34: 3 | J34: WH | K34: WHACG2323A | L34: Denim Chain Stitch Ball Cap | M34: 물류 | N34: 입고 | O34: 완료 | P34: 39900 | Q34: 2025-12-24 | R34: 46027 | Z34: (55)Indigo | AA34: (56)Light Indigo | AK34: G
B35: 2025-11-28 | C35: 45992 | D35: 45993 | E35: 45995 | F35: 3 | G35: A | H35: G2 | I35: 3 | J35: WH | K35: WHACG2351A | L35: Bear Embroidery Ball Cap[B] | M35: 물류 | N35: 입고 | O35: 완료 | P35: 39900 | Q35: 2025-11-28 | S35: 45996 | T35: 7 | V35: 등록 | Z35: (26)Light Pink | AA35: (51)Light Blue | AB35: (64)Cream | AI35: 1 | AJ35: 3 | AK35: G
B36: 2026-1-15 | C36: 46038 | D36: 46049 | E36: 46049 | F36: 11 | G36: A | H36: G2 | I36: 5 | J36: WH | K36: WHAPG2521A | L36: Steve Flip-flops | M36: 물류 | N36: 입고 | O36: 완료 | P36: 29900 | Q36: 2026-01-15 | Z36: (39)Ivory | AA36: (76)Light Purple | AB36: (91)Silver | AJ36: 11 | AK36: G
B37: 2026-1-15 | C37: 46038 | D37: 46049 | E37: 46049 | F37: 11 | G37: A | H37: G2 | I37: 5 | J37: WH | K37: WHAPG2522A | L37: Steve Summer Clog | M37: 물류 | N37: 입고 | O37: 완료 | P37: 29900 | Q37: 2026-01-15 | Z37: (19)Black | AA37: (39)Ivory | AJ37: 11 | AK37: G
B38: 2026-1-5 | C38: 46028 | D38: 46037 | E38: 46038 | F38: 10 | G38: A | H38: G2 | I38: 2 | J38: WH | K38: WHAWG2221A | L38: Steve Denim Keyring | M38: 물류 | N38: 입고 | O38: 완료 | P38: 19900 | Q38: 2026-01-05 | R38: 46028 | Z38: (55)Indigo | AA38: (56)Light Indigo | AK38: G
B39: 2026-1-5 | C39: 46028 | D39: 46048 | E39: 46048 | F39: 20 | G39: A | H39: G2 | I39: 2 | J39: WH | K39: WHAWG2222A | L39: Fluffy Bear Knit Keyring | M39: 물류 | N39: 입고 | O39: 완료 | P39: 19900 | Q39: 2026-01-05 | Z39: (20)Red | AA39: (39)Ivory | AB39: (59)Navy | AK39: G
B40: 2026-1-5 | C40: 46028 | D40: 46037 | E40: 46038 | F40: 10 | G40: A | H40: G2 | I40: 2 | J40: WH | K40: WHAWG2223A | L40: Fluffy Bear Mini Bag Charm | M40: 물류 | N40: 입고 | O40: 완료 | P40: 19900 | Q40: 2026-01-05 | Z40: (20)Red | AK40: G
...
